Workbook

Sheet اقرأني
A1: سجل «دليل» — منهجية العمل
A3: 1. كل جديد يدخل «للمراجعة» | B3: كل مقطع يُستخرج وكل قالب جديد أو معدّل يوضع في ورقة «للمراجعة» فقط. لا يُنشر شيء منها.
A4: 2. القرار | B4: في «للمراجعة» تكتب: القرار (معتمد / معتمد بتعديل / مرفوض)، والتعديل أو الملاحظة، والمراجع والتاريخ. المقطع الحساس يحتاج أيضاً «موافق» في عمود رأي المختص الأعلم.
A5: 3. النقل | B5: بعد القرار ينقل السكربت scripts/promote.py: «معتمد» ← إلى «المقاطع» أو «القوالب» مع ملاحظتك في «ملاحظات الاعتماد». «معتمد بتعديل» ← يُنفَّذ التعديل أولاً ثم يُنقل مع ذكر التعديل. «مرفوض» ← إلى «المرفوض» مع السبب.
A6: 4. المنشور | B6: المنتج لا يقرأ إلا «المقاطع» و«القوالب»، ويعيد التحقق من الشروط عند التصدير.
A7: 5. الناقص | B7: مقاطع مخططة لم يُستخرج نصها بعد، مع المصدر المرشح.
A9: أسس الصحة | B9: النص حرفي من موضع محدد · المصدر معتمد بعنوان ورابط · المستوى أ أو ب · مراجعة موثقة باسم وتاريخ · الحساس بموافقة المختص الأعلم · الآيات تُعرض من نص المصحف.
A10: الفحوص السبعة (للمراجع) | B10: ١ يجيب عن السؤال المنسوب · ٢ لا يحذف قيداً أو سياقاً · ٣ لا يعرض اعتراضاً دون جواب · ٤ المعرفة السابقة واضحة · ٥ النقل والمصطلحات سليمة · ٦ النص حرفي في الموضع · ٧ لا قطع في خلاف
A11: الألوان | B11: أصفر: تكتب فيه · رمادي: معادلة · برتقالي: حساس · أخضر: صالح للنشر
A12: النسخة | B12: v13 — 4 أكتوبر 2026

Sheet للمراجعة
A1: النوع | B1: الرقم | C1: الحاجة أو متى يُستخدم | D1: الأولوية | E1: المصدر | F1: الموضع | G1: عنوان المسألة | H1: السؤال في المصدر | I1: عبارات مشابهة | J1: مضمون السؤال | K1: النص | L1: يجيب هذا المقطع عن | M1: صياغات المستخدم | N1: المستوى | O1: حساس؟ | P1: آيات وأحاديث للتوثيق | Q1: ملاحظات الاستخراج | R1: ما المطلوب من المختص | S1: القرار | T1: التعديل أو الملاحظة | U1: المراجع والتاريخ | V1: رأي المختص الأعلم | W1: لا يُجتزأ | X1: أسئلة قريبة لا يجيب عنها | Y1: للتفصيل فقط | Z1: تنبيه المراجع

Sheet المقاطع
A1: رقم | B1: الحاجة | C1: الأولوية | D1: المصدر | E1: الموضع | F1: عنوان المسألة | G1: السؤال في المصدر | H1: عبارات مشابهة | I1: مضمون السؤال | J1: النص المعتمد | K1: يجيب هذا المقطع عن | L1: صياغات المستخدم | M1: المستوى | N1: حساس؟ | O1: آيات وأحاديث (توثيق) | P1: اعتمده (المراجع والتاريخ) | Q1: رأي المختص الأعلم | R1: ملاحظات الاعتماد | S1: صالح للنشر | T1: لا يُجتزأ | U1: أسئلة قريبة لا يجيب عنها | V1: للتفصيل فقط | W1: تنبيه المراجع
A2: ق-32 | B2: ح1 | C2: إضافي | D2: م-01 | E2: المسألة (119)، ص545–ص546 — مختصر الإجابة | F2: هل القرآن الكريم يغني عن السنة النبوية؟ | G2: إن القرآن الكريم يغني عن السنة النبوية؛ ويدل على ذلك قوله تعالى: ﴿ونزلنا عليك الكتاب تبيانا لكل شيء﴾ [النحل: 89]، وقوله: ﴿ما فرطنا في الكتاب من شيء﴾ [الأنعام: 38]. | H2: هل صحيح أن الدين يؤخذ من القرآن، وأما السنة النبوية، فاجتهادات شخصية؟ | I2: تأتي هذه الشبهة في مقولة تظهر صاحبها في صورة المكتفي بالقرآن مصدرا للحجة والاستدلال، فإذا استدللت لحكم شرعي بدليل من السنة النبوية، قذف بهذه المقولة في وجهك، مدعيا كفاية القرآن في إقامة الدين، دون الحاجة إلى مصدر آخر. | J2: حجية السنة النبوية ثابتة بالأدلة المتنوعة من العقل والنقل؛ فالقول بعدم حجية السنة مناقض للقرآن، كما أن إنكار السنة له من اللوازم الفاسدة العائدة على الدين بالإبطال العدد الكبير؛ فإنكار السنة النبوية يؤدي إلى تعذر إقامة الدين، وإضاعة مصدر من مصادر تبيين معاني القرآن، لا عوض عنه، والطعن في النبي ﷺ بنسبته إلى الافتراء والتضليل والتلبيس، مما يؤدي إلى رد ما جاء به، مع ما فيه من قلة الأدب معه ﷺ. | K2: يبين أن السنة النبوية حجة، وأنها مصدر لتبيين معاني القرآن لا يُستغنى عنه. | L2: هل نكتفي بالقرآن عن السنة؟ | لماذا لا يكفي القرآن وحده؟ | هل السنة ضرورية لفهم القرآن؟ | M2: ب | N2: نعم | O2: لا يوجد في المختصر (آيتان في نص السؤال); آية في السؤال المصدري | P2: محمد — 2026-10-04 | Q2: موافق | R2: مراجعة النقل: مطابق دون ملاحظات. مقطع حساس: وافق المختص الأعلم دون تعديل (2026-10-04). [5 أكتوبر] عُدّلت بيانات التوجيه بعد مراجعة اللجنة الخارجية؛ النص المعتمد لم يتغير. «لا يُجتزأ»: مقطع حجاجي يُعرض كاملاً حتى لا تُقتطع نتيجة دون حجتها (ملاحظة اللجنة). | S2: =IF(A2="","",IF(OR(M2="ج",M2="د"),"المستوى لا يُنشر",IF(IFERROR(INDEX(المصادر!$F$2:$F$30,MATCH(D2,المصادر!$A$2:$A$30,0)),"")<>"نعم","المصدر غير معتمد",IF(OR(B2="",E2="",J2="",K2="",P2=""),"بيانات ناقصة",IF(AND(N2="نعم",Q2<>"موافق"),"ينقصه رأي المختص","صالح للنشر"))))) | T2: نعم | U2: ما علاقة القرآن بالكتب السابقة؟ | ما تعريف القرآن؟ | ما مكانة القرآن عند المسلمين؟ | ما علاقة الحديث بالقرآن؟ | ما الفرق بين القرآن والحديث؟
A3: ق-29 | B3: ح2 | C3: إضافي | D3: م-01 | E3: المسألة (40)، ص192–ص192 — مختصر الإجابة | F3: اختلاف أسلوب القرآن المكي والمدني. | G3: تغير أسلوب القرآن المدني عن القرآن المكي من الشدة إلى اللين، يدل على تأثره بالبيئة؛ وهذا يدل على أنه من فعل البشر. | H3: هل تأثر أسلوب القرآن بالبيئة التي نزل فيها؟ | I3: — | J3: احتوى القرآن المكي والمدني على أسلوبي اللين والشدة معا؛ حيث نجد الشدة في القرآن المدني، واللين في القرآن المكي؛ رعاية لحال المخاطبين؛ فمن يقرأ القرآن بتأمل، يجد أن القرآن كله قام على رعاية حال المخاطبين؛ فتارة: يخاطبهم بالترغيب، وتارة: يخاطبهم بالترهيب؛ تبعا لما يقتضيه حال المخاطبين؛ سواء منهم مكيهم ومدنيهم؛ ولهذا نجد أنه لم يقل أحد من كفار قريش أو غيرهم بهذا القول المذكور في السؤال، مع إحاطتهم التامة باللغة، وحرصهم الشديد على إيجاد أي خلل في القرآن الكريم؛ خاصة مع تحديهم أن يأتوا ولو بسورة من مثله. | K3: يبين أن القرآن المكي والمدني كليهما فيه اللين والشدة، وأن الخطاب يراعي حال المخاطبين. | L3: هل القرآن المكي كله شدة والمدني كله لين؟ | لماذا يشتد خطاب القرآن أحياناً ويلين أحياناً؟ | M3: ب | N3: لا | O3: لا يوجد في المختصر | P3: محمد — 2026-10-04 | R3: مراجعة النقل: مطابق دون ملاحظات. [5 أكتوبر] عُدّلت بيانات التوجيه بعد مراجعة اللجنة الخارجية؛ النص المعتمد لم يتغير. | S3: =IF(A3="","",IF(OR(M3="ج",M3="د"),"المستوى لا يُنشر",IF(IFERROR(INDEX(المصادر!$F$2:$F$30,MATCH(D3,المصادر!$A$2:$A$30,0)),"")<>"نعم","المصدر غير معتمد",IF(OR(B3="",E3="",J3="",K3="",P3=""),"بيانات ناقصة",IF(AND(N3="نعم",Q3<>"موافق"),"ينقصه رأي المختص","صالح للنشر"))))) | U3: كيف نزل القرآن؟ | في أي شهر نزل القرآن؟ | ما معنى سورة مكية؟ | ما الفرق بين أسلوب السور المكية والمدنية؟
A4: ق-30 | B4: ح2 | C4: إضافي | D4: م-01 | E4: المسألة (103)، ص472–ص473 — مختصر الإجابة | F4: لماذا يكون الوحي بطرق خفية، ولا يأتي جبريل بصورته الحقيقية مبلغا الناس ما يريده؟ | G4: لماذا كان الوحي بطريقة خفية؟ فالوحي عند علماء الإسلام: هو الإخبار في سرعة وخفاء؛ فلماذا لا يجعل الله إيصال ما يريده إلى النبي بطريقة واضحة وظاهرة للناس؛ كأن يرسل جبريل في صورته الحقيقية، ويبلغ الرسول بصوت واضح ما يريده؟ | H4: هل الوحي يجب أن يأتي به الملك بصورته الحقيقية؟ | I4: إن إرسال جبريل في صورته الحقيقية، مبلغا الرسول بصوت واضح ما يريده، هو الأمر الأولى في صور الوحي من وجهة نظر السائل، دون الطرق الخفية. | J4: إن البراهين دلت دلالة قاطعة على صدق النبوة؛ وهذا هو المطلوب للتصديق بالرسول واتباعه، وليس المطلوب معرفة الطريقة التي جاء بها الوحي. ثم حتى لو جاء الوحي بطريقة ظاهرة، ولكنه جاء على صورة بشر؛ فما الذي سيتغير؟! سيكذبونه كما كذبوا رسول الله ﷺ. ثم هو أيضا نوع من الاختبار؛ وإلا فالله تعالى قادر على أن ينزل الملائكة بأسواط من النار لمن يعصون الله تعالى، وأطواق من الذهب لمن يطيعونه، ولكن ذلك يخالف حكمة الابتلاء. وعدم معرفتهم بطريقة إتيان جبريل، لا ينفي وجوده؛ لأن عدم العلم بطريقة الشيء لا يستلزم الحكم عليه بعدم الصحة، أو عدم الوقوع. | K4: يبين أن المطلوب هو التصديق بالنبوة بأدلتها، لا معرفة كيفية مجيء الوحي، وأن خفاء الطريقة من حكمة الابتلاء. | L4: لماذا لم ير الناس جبريل؟ | لماذا كان الوحي خفيا؟ | M4: ب | N4: نعم | O4: — | P4: محمد — 2026-10-04 | Q4: موافق | R4: مراجعة النقل: مطابق دون ملاحظات. مقطع حساس: وافق المختص الأعلم دون تعديل (2026-10-04). «لا يُجتزأ»: مقطع حجاجي يُعرض كاملاً حتى لا تُقتطع نتيجة دون حجتها (ملاحظة اللجنة). | S4: =IF(A4="","",IF(OR(M4="ج",M4="د"),"المستوى لا يُنشر",IF(IFERROR(INDEX(المصادر!$F$2:$F$30,MATCH(D4,المصادر!$A$2:$A$30,0)),"")<>"نعم","المصدر غير معتمد",IF(OR(B4="",E4="",J4="",K4="",P4=""),"بيانات ناقصة",IF(AND(N4="نعم",Q4<>"موافق"),"ينقصه رأي المختص","صالح للنشر"))))) | T4: نعم | U4: كيف كان الوحي يأتي النبي؟ | متى بدأ نزول الوحي؟
A5: ق-11 | B5: ح3 | C5: أساسي | D5: م-01 | E5: المسألة (42)، ص201–ص201 — الجواب التفصيلي | F5: ادعاء أن القرآن لم يدون كله ولم يجمع في عهد النبي ﷺ. | G5: لم يجمع القرآن كتابة في عهد النبي، وقد وقع التحريف والتبديل حين جمعه الصحابة؛ والدليل اختلافهم في بعض الآيات. | H5: جمع القرآن. | تدوين القرآن الكريم. | I5: عن تدوين القرآن وجمعه، هل تم كل ذلك في عهد النبي ﷺ، فإذا لم يحصل، كان هذا دليلا على إمكانية وقوع التحريف فيه. | J5: أولا: لقد حفظ الله القرآن لنبيه ﷺ، بطرق عديدة، منها: 1) حفظه في صدور كثير من الصحابة بعد تلقي النبي ﷺ له على مدى ثلاث عشرة سنة في مكة، وعشر سنين في المدينة. 2) وحفظه بتدوينه من قبل كتبة الوحي فور تلقي النبي ﷺ إياه. 3) ثم بمعارضة جبريل القرآن عليه كل عام مرة، ومعارضته عام وفاته له ﷺ مرتين. 4) وكتبته -وهم الصحابة- عدول ثقات، ثبتت عدالتهم بأدلة كثيرة، ولا يمكن تواطؤهم على الكذب أو الغلط في مثل هذا الأمر الذي هو أعظم ما يعنون به؛ حفظا وفهما، وتدارسا وعملا ونشرا. 5) وقد جمع القرآن كله في حياة النبي ﷺ في صحف ورقاع، مرتبا كما هو الآن، إلا أنه لم يكن في مصحف واحد. | K5: يعدد الطرق التي حُفظ بها القرآن زمن النبي ﷺ: الحفظ في صدور الصحابة، والتدوين فور النزول، ومعارضة جبريل له كل عام، وعدالة كتبته. | L5: كيف حُفظ القرآن زمن النبي؟ | هل كان الصحابة يحفظون القرآن؟ | كيف دُوّن القرآن في حياة النبي؟ | M5: أ | N5: لا | O5: البند 3 يشير إلى حديث معارضة جبريل للنبي ﷺ (البخاري) دون نصه — يُوثَّق من الدرر | P5: محمد — 2026-10-04 | R5: مراجعة النقل: مطابق دون ملاحظات. [5 أكتوبر] عُدّلت بيانات التوجيه بعد مراجعة اللجنة الخارجية؛ النص المعتمد لم يتغير. للمراجعة: «مرتباً كما هو الآن» هنا، وق-17 يذكر الخلاف في ترتيب السور؛ هل يحتاج توضيحاً؟ | S5: =IF(A5="","",IF(OR(M5="ج",M5="د"),"المستوى لا يُنشر",IF(IFERROR(INDEX(المصادر!$F$2:$F$30,MATCH(D5,المصادر!$A$2:$A$30,0)),"")<>"نعم","المصدر غير معتمد",IF(OR(B5="",E5="",J5="",K5="",P5=""),"بيانات ناقصة",IF(AND(N5="نعم",Q5<>"موافق"),"ينقصه رأي المختص","صالح للنشر"))))) | U5: في أي شهر نزل القرآن؟ | هل نزل القرآن مفرقاً؟ | متى جُمع القرآن في مصحف واحد؟ | من كان يكتب الوحي؟
A6: ق-12 | B6: ح3 | C6: أساسي | D6: م-01 | E6: المسألة (42)، ص200–ص201 — مختصر الإجابة | F6: ادعاء أن القرآن لم يدون كله ولم يجمع في عهد النبي ﷺ. | G6: لم يجمع القرآن كتابة في عهد النبي، وقد وقع التحريف والتبديل حين جمعه الصحابة؛ والدليل اختلافهم في بعض الآيات. | H6: جمع القرآن. | تدوين القرآن الكريم. | I6: عن تدوين القرآن وجمعه، هل تم كل ذلك في عهد النبي ﷺ، فإذا لم يحصل، كان هذا دليلا على إمكانية وقوع التحريف فيه. | J6: حفظ الله سبحانه كتابه الكريم؛ وهذا هو الضمان الأول والأقوى، وعدم جمع القرآن في مصحف واحد في عهد النبي كان لعدم اكتماله بعد آنذاك. وقد كتب القرآن الكريم ثلاث مرات: مرة: في حياة النبي ﷺ في صحف ورقاع، مرتبة آياته كما هي الآن، إلا أنه لم يكن في مصحف واحد؛ لأنه لم يكن اكتمل بعد إلى قرب وفاته ﷺ، ولم يكن المسلمون يحتاجون لجمعه والنبي ﷺ بين ظهرانيهم، وكان الكثير من الصحابة يحفظونه في صدورهم. وثانية: في عهد أبي بكر رضي الله عنه. وثالثة: في عهد عثمان رضي الله عنه. وقد تم جمع القرآن الكريم في مصحف واحد في عهد عثمان وفق منهج علمي محكم كان غاية في الدقة، ووفق ضوابط بالغة الإتقان يلفها الحرص من كل جانب؛ بحيث لم يقبل الصحابة غير قطعي الثبوت، ويأبى عليهم دينهم وعقلهم أن يثبتوا ما ليس بقطعي. وكان من نتيجة ذلك الجهد العظيم: أن القرآن الذي نقرؤه اليوم هو القرآن نفسه الذي نزل على الرسول ﷺ، ولم يتغير حرف واحد فيه؛ وذلك بشهادة الكثير من أهل الغرب أنفسهم من أصحاب الدراسات الدينية المقارنة؛ والحمد لله رب العالمين. | K6: يبين أن القرآن كُتب ثلاث مرات: في حياة النبي ﷺ في صحف متفرقة، ثم في عهد أبي بكر، ثم جُمع في مصحف واحد في عهد عثمان رضي الله عنهما. | L6: كيف جُمع القرآن؟ | لماذا لم يُجمع القرآن في كتاب واحد زمن النبي؟ | متى كُتب القرآن؟ | M6: أ | N6: لا | O6: — | P6: محمد — 2026-10-04 | R6: مراجعة النقل: مطابق دون ملاحظات. | S6: =IF(A6="","",IF(OR(M6="ج",M6="د"),"المستوى لا يُنشر",IF(IFERROR(INDEX(المصادر!$F$2:$F$30,MATCH(D6,المصادر!$A$2:$A$30,0)),"")<>"نعم","المصدر غير معتمد",IF(OR(B6="",E6="",J6="",K6="",P6=""),"بيانات ناقصة",IF(AND(N6="نعم",Q6<>"موافق"),"ينقصه رأي المختص","صالح للنشر"))))) | U6: كيف كان الوحي ينزل على النبي؟ | كم عدد الحفاظ من الصحابة؟
A7: ق-13 | B7: ح3 | C7: إضافي | D7: م-01 | E7: المسألة (48)، ص225–ص226 — مختصر الإجابة | F7: هل ضاع شيء من القرآن الذي سمعه الصحابة من النبي ﷺ؛ بسبب جمع عثمان للقرآن؟ | G7: هل ضاع شيء من القرآن الذي سمعه الصحابة من النبي ﷺ؛ بسبب جمع عثمان للقرآن؟ | H7: ألم يكن في إلزام عثمان للصحابة بمصحف واحد، وترك ما بأيديهم، ترك لما سمعوه من النبي على أنه قرآن؟ | I7: — | J7: لم ينفرد عثمان بن عفان رضي الله عنه بقرار جمع المسلمين على مصحف واحد؛ بل كان القرار باجتماع عدد من الصحابة العدول الثقات، وقد وافقه على ذلك وأقره بقية الصحابة؛ وعلى هذا سارت الأمة الإسلامية. وقد كان الغرض من ذلك الجمع: هو منع انتشار الفتنة بين المسلمين نتيجة اختلاف قراءاتهم للقرآن؛ وهذه مصلحة عظيمة. ولذلك: فقد تم جمع القرآن لأسباب وجيهة، وكان وفق معايير صارمة؛ وهو ما تميزت به تلك العملية من مزايا؛ ومنها: 1) أن يقتصر الجمع على ما ثبت في العرضة الأخيرة. 2) عدم جمع ما نسخت تلاوته. 3) جميع من شهد الجمع من الصحابة شاركوا فيه. 4) يدخل في الجمع ما ثبت بالتواتر فحسب، وأهملت روايات الآحاد. 5) تم ترتيب السور والآيات على الصورة التي لدينا الآن. وغير ذلك من المزايا التي جعلت ذلك العمل من أهم الأعمال وأكثرها قيمة في تاريخ الإسلام. | K7: يوضح أن جمع عثمان رضي الله عنه للناس على مصحف واحد كان باتفاق الصحابة لمنع الاختلاف، ويذكر ضوابط ذلك الجمع. | L7: لماذا جمع عثمان القرآن؟ | هل ضاع شيء من القرآن بجمع عثمان؟ | لماذا جمع عثمان الناس على مصحف واحد؟ | M7: ب | N7: نعم | O7: — | P7: محمد — 2026-10-04 | Q7: موافق | R7: مراجعة النقل: مطابق دون ملاحظات. مقطع حساس: وافق المختص الأعلم دون تعديل (2026-10-04). [5 أكتوبر] عُدّلت بيانات التوجيه بعد مراجعة اللجنة الخارجية؛ النص المعتمد لم يتغير. «لا يُجتزأ»: مقطع حجاجي يُعرض كاملاً حتى لا تُقتطع نتيجة دون حجتها (ملاحظة اللجنة). | S7: =IF(A7="","",IF(OR(M7="ج",M7="د"),"المستوى لا يُنشر",IF(IFERROR(INDEX(المصادر!$F$2:$F$30,MATCH(D7,المصادر!$A$2:$A$30,0)),"")<>"نعم","المصدر غير معتمد",IF(OR(B7="",E7="",J7="",K7="",P7=""),"بيانات ناقصة",IF(AND(N7="نعم",Q7<>"موافق"),"ينقصه رأي المختص","صالح للنشر"))))) | T7: نعم | U7: كيف كُتب القرآن زمن النبي؟ | ما القراءات؟ | ما الفرق بين جمع أبي بكر وجمع عثمان؟
A8: ق-14 | B8: ح3 | C8: إضافي | D8: م-01 | E8: المسألة (43)، ص204–ص205 — مختصر الإجابة | F8: ادعاء أن نقل الصحابة للقرآن نقل آحادي لا متواتر. | G8: جاءت روايات تدل أن القرآن الكريم أخذ عن عدد قليل من الصحابة لا يتجاوز أصابع اليد؛ وهذا يبطل دعوى تواتره. كما في «الصحيحين»، عن أنس بن مالك، قال: «جمع القرآن على عهد النبي ﷺ أربعة، كلهم من الأنصار: أبي بن كعب، ومعاذ بن جبل، وزيد بن ثابت، وأبو زيد». | H8: هل ثبت أن القرآن متواتر؟ | كم عدد الصحابة الذين نقلوا القرآن؟ | I8: يدور السؤال حول نقل الصحابة للقرآن الكريم، وهل تحقق وفق شروط التواتر؛ لوجود مرويات حددت أعدادا محدودة من الصحابة يؤخذ عنهم القرآن؟ | J8: 1) الروايات التي تحصر أخذ القرآن أو حفظه بعدد محدد من الصحابة، ليس فيها معنى الحصر الذي يراد نفي ما سواه؛ فهي تفهم بالروايات الأخرى الصحيحة الدالة على أن عددهم كثير. وأما روايات حصر حفظة القرآن بعدد محدد، فلها وجوه تفهم من السياق ومن النصوص الأخرى؛ كأن يكون المقصود التمثيل لا الحصر، أو ذكر المتقدمين من حفظة القرآن، أو ذكر من جمع القرآن مكتوبا لنفسه، أو من جمعه على الوجوه والأحرف المختلفة. 2) واقع الصحابة في حرصهم الشديد على حفظ كتاب الله سبحانه في الصدور والسطور، واهتمامهم به، وتنافسهم فيه، ونقل بعضهم عن بعض، بل ارتبطت حياتهم كلها في ليلهم ونهارهم بآيات القرآن رباطا وثيقا -: يبطل هذه الدعوى. | K8: يبين أن حفظة القرآن من الصحابة كانوا كثيرين، وأن الروايات التي تذكر عددا قليلا لا يُقصد بها الحصر. | L8: كم عدد الصحابة الذين حفظوا القرآن؟ | هل نُقل القرآن عن عدد قليل؟ | كيف وصل القرآن إلينا؟ | M8: ب | N8: نعم | O8: يشير إلى روايات الحصر (حديث أنس في الصحيحين، مذكور في السؤال لا في المقطع); حديث أنس في السؤال المصدري | P8: محمد — 2026-10-04 | Q8: موافق | R8: مراجعة النقل: مطابق دون ملاحظات. مقطع حساس: وافق المختص الأعلم دون تعديل (2026-10-04). «لا يُجتزأ»: مقطع حجاجي يُعرض كاملاً حتى لا تُقتطع نتيجة دون حجتها (ملاحظة اللجنة). | S8: =IF(A8="","",IF(OR(M8="ج",M8="د"),"المستوى لا يُنشر",IF(IFERROR(INDEX(المصادر!$F$2:$F$30,MATCH(D8,المصادر!$A$2:$A$30,0)),"")<>"نعم","المصدر غير معتمد",IF(OR(B8="",E8="",J8="",K8="",P8=""),"بيانات ناقصة",IF(AND(N8="نعم",Q8<>"موافق"),"ينقصه رأي المختص","صالح للنشر"))))) | T8: نعم | U8: كيف جمع عثمان القرآن؟ | كيف أحفظ القرآن؟
A9: ق-17 | B9: ح4 | C9: أساسي | D9: م-01 | E9: المسألة (54)، ص249–ص250 — مختصر الإجابة | F9: ادعاء أن ترتيب آيات القرآن من فعل الصحابة. | G9: ما دام الصحابة قد رتبوا آيات القرآن؛ فهذا دليل على تحريفهم لآيات القرآن؛ كما يمكن بسبب ذلك وقوع الأخطاء فيه، والإدخال عليه. | H9: ترتيب آيات القرآن. | ترتيب الصحابة للمصحف. | I9: بحسب وجهة نظر صاحب السؤال: لم تكن هناك دقة لدى الصحابة في تلقيهم القرآن عن رسول الله ﷺ، وهو يستبعد أن يكونوا قد حافظوا عليه، وعلى ترتيب آياته وسوره، وفق ما سمعوه من الرسول ﷺ. | J9: يزول هذا الإشكال من خلال معرفة الحال التي جرى عليها كتابة المصحف وترتيبه؛ فترتيب الآيات والسور كان وفق إرادة الله وحده؛ أوحاه لنبيه ﷺ، ووفقه إليه، وسار عليه صحابته رضوان الله عليهم من بعده؛ وذلك كالتالي: 1) ترتيب الآيات في كل سورة أمر توقيفي من الله تعالى، ومن النبي ﷺ، وقراءة الرسول ﷺ للآيات بالترتيب الذي أوحاه له جبريل، بينت موضع كل آية في كل سور القرآن. 2) أما ترتيب السور في المصحف، فمختلف في كونه توقيفيا؛ فقد قال بعضهم: إن كل سورة مستقلة بإعجازها، وأما ترتيبها، فموكول إلى الناس، لكن يظهر أنه أمر توقيفي أيضا، وقد توافق عليه الصحابة آخر الأمر؛ وهو مذهب جمهور العلماء. ووجود اختلاف بين الصحابة في بعض ذلك، فربما لأن بعضهم ظنها أمرا اجتهاديا، أو لأنه رتبه على ما سمعه من النبي ﷺ، دون ما كان في آخر عرضة للقرآن؛ لأن جبريل كان يدارس النبي ﷺ القرآن كل عام. ولو افترض تدخل الصحابة في الترتيب، فلا يدل على التحريف، ولا على ضعف معانيه، وليس له أي أثر في وقوع تحريف أو سقط أو زيادة، بل غاية ما فيه: تقديم بعض المواضع على بعض؛ مما لا يتعلق بذات النص. | K9: يبين أن ترتيب الآيات داخل كل سورة من الوحي، ويذكر خلاف العلماء في ترتيب السور وأن الجمهور على أنه توقيفي. | L9: من رتّب سور القرآن؟ | لماذا ترتيب المصحف ليس بحسب النزول؟ | هل ترتيب الآيات من الصحابة؟ | M9: ب | N9: نعم | O9: يشير إلى مدارسة جبريل للنبي ﷺ القرآن كل عام (البخاري) دون نصه | P9: محمد — 2026-10-04 | Q9: موافق | R9: مراجعة النقل: مطابق دون ملاحظات. مقطع حساس: وافق المختص الأعلم دون تعديل (2026-10-04). «لا يُجتزأ»: مقطع حجاجي يُعرض كاملاً حتى لا تُقتطع نتيجة دون حجتها (ملاحظة اللجنة). | S9: =IF(A9="","",IF(OR(M9="ج",M9="د"),"المستوى لا يُنشر",IF(IFERROR(INDEX(المصادر!$F$2:$F$30,MATCH(D9,المصادر!$A$2:$A$30,0)),"")<>"نعم","المصدر غير معتمد",IF(OR(B9="",E9="",J9="",K9="",P9=""),"بيانات ناقصة",IF(AND(N9="نعم",Q9<>"موافق"),"ينقصه رأي المختص","صالح للنشر"))))) | T9: نعم | U9: كم عدد سور القرآن؟ | لماذا تتنقل السورة بين موضوعات مختلفة؟
A10: ق-28 | B10: ح4 | C10: إضافي | D10: م-01 | E10: المسألة (53)، ص246–ص246 — مختصر الإجابة | F10: ادعاء أن آيات القرآن وسوره غير مرتبة. | G10: القرآن غير مرتب ولا منظم؛ سواء على المواضيع أو الأزمنة، فلم يفرد كل غرض من أغراضه بفصل أو باب أو زمن نزول، غير مراعى فيه نظام التأليف؛ فيبعد أن يكون وحيا من الله. | H10: لماذا ترتيب القرآن وتنظيمه وترتيب مواضيعه، ليس مثل الكتب المرتبة موضوعيا أو زمنيا؟ | I10: — | J10: ترتيب القرآن الكريم له حكمته الخاصة. وكون القرآن الكريم لا يشابه أي كتب بشرية، في أنظمتها، وأسلوبها، فليس في ذلك أي قدح، إنما القدح لو كان ذلك سببا للنقص، وغيره أولى به. بل ذكر العلماء في ذلك وجوها تبين كماله، وأنه كلام الله، لا كلام البشر؛ فالتصنيف قد يؤطر المعاني، ثم قد يوهم انفصال المعاني بعضها عن بعض، لكنه جاء بهذا النظم المعجز الذي يأخذ بالألباب، ويثير فيها المعاني المختلفة، ولا يفصل الفكرة عن السلوك، ولا عن المشاعر، ولغير ذلك من الحكم؛ وهذا غاية الكمال الذي يقتضي المدح والمزية، وأنه كتاب سماوي منزل من عند الله سبحانه، وقد ظنه السائل نقصا مقتضيا للطعن والذم، وأنه من صنع البشر. | K10: يبين أن ترتيب القرآن غير الموضوعي له حكمة، وأن مزج الموضوعات في السورة الواحدة من كماله لا نقصه. | L10: لماذا لا يُقسَّم القرآن إلى فصول؟ | لماذا تتنقل السورة بين موضوعات مختلفة؟ | M10: ب | N10: لا | O10: — | P10: محمد — 2026-10-04 | R10: مراجعة النقل: مطابق دون ملاحظات. | S10: =IF(A10="","",IF(OR(M10="ج",M10="د"),"المستوى لا يُنشر",IF(IFERROR(INDEX(المصادر!$F$2:$F$30,MATCH(D10,المصادر!$A$2:$A$30,0)),"")<>"نعم","المصدر غير معتمد",IF(OR(B10="",E10="",J10="",K10="",P10=""),"بيانات ناقصة",IF(AND(N10="نعم",Q10<>"موافق"),"ينقصه رأي المختص","صالح للنشر"))))) | U10: من رتّب سور القرآن؟ | ما أبرز موضوعات القرآن؟
A11: ق-31 | B11: ح6 | C11: إضافي | D11: م-01 | E11: المسألة (94)، ص423–ص424 — مختصر الإجابة | F11: عدم موافقة ترجمة القرآن لجميع معانيه. | G11: لا يمكن أن يكون القرآن بلاغا للعالمين؛ لأنه لا يمكن تفسيره؛ لأن الترجمة الحرفية غير ممكنة؛ لاختلاف اللغتين في طريق توصيل المعنى، وكذلك التفسير بالمعنى سيكون قاصرا عن تأدية جميع معاني القرآن؛ وفي كلا الحالين: سيكون التفسير ناقصا، وبالتالي يكون مقتصرا على العرب الفصحاء، وليس بلاغا للعالمين. | H11: لماذا لا تطابق ترجمة القرآن جميع معانيه؟ | I11: — | J11: الترجمة الصحيحة تؤدي المطلوب، وتجعل الآية تلتئم مع ما قبلها، ومع ما بعدها؛ فهذه الدعوى في السؤال لا تصح؛ ويظهر ذلك بأمور: 1) الإسلام دين للعالم أجمع، ورسوله بعث للعالمين، والبلاغ شرط لزوم الرسالة؛ فلا بد من ترجمة معاني القرآن بلسان تلك الأمم؛ من أجل دعوتهم وإلزامهم الحجة؛ فلترجمة معاني القرآن الكريم فوائد جمة تعود للداعي والمدعو والدعوة، ولا ينبغي تركها لمثل هذه الأسباب. 2) تفسير القرآن بلسان أعجمي، له نفس حكم تفسيره بلسان عربي؛ فالمفسر يقدم في الحالتين ما فهمه من كتاب الله، بلغة يفهمها من يخاطبهم، ولا يقدم ترجمة القرآن نفسه؛ وفي كلتا الحالتين: حكاية لما يستطاع من المقاصد لتفسير القرآن، وليس كل المقاصد؛ فيكفي في تحقق ذلك أن يكون بيانا لمراد الله، حتى ولو جاء على احتمال واحد؛ فالتفسير العربي لا يتطلب كل الأمور التي ذكرت في السؤال. 3) ما لا يطلب في التفسير العربي لا يطلب في الترجمة من باب أولى؛ لأن التفسير بيان لأحد الأوجه، لا لجميع الأوجه؛ ولذلك تنوعت التفاسير. | K11: يبين أن ترجمة معاني القرآن نوع من التفسير بلغة أخرى، تنقل ما فهمه المترجم لا نص القرآن نفسه. | L11: هل الترجمة هي القرآن؟ | هل أستطيع فهم القرآن من ترجمة؟ | M11: ب | N11: لا | O11: — | P11: محمد — 2026-10-04 | R11: مراجعة النقل: مطابق دون ملاحظات. | S11: =IF(A11="","",IF(OR(M11="ج",M11="د"),"المستوى لا يُنشر",IF(IFERROR(INDEX(المصادر!$F$2:$F$30,MATCH(D11,المصادر!$A$2:$A$30,0)),"")<>"نعم","المصدر غير معتمد",IF(OR(B11="",E11="",J11="",K11="",P11=""),"بيانات ناقصة",IF(AND(N11="نعم",Q11<>"موافق"),"ينقصه رأي المختص","صالح للنشر"))))) | U11: ما أفضل ترجمة للقرآن؟ | ما هو التفسير؟ | هل تجوز الصلاة بترجمة القرآن؟
A12: ق-23 | B12: ح7 | C12: أساسي | D12: م-01 | E12: المسألة (84)، ص377–ص378 — مختصر الإجابة | F12: تحدى القرآن البشر أن يأتوا بمثله، مع وجود كلام في غاية البلاغة للبشر. | G12: تحدى القرآن البشر أن يأتوا بمثله، وقد رأينا في كلام كثير من الناس والشعراء غاية البلاغة؛ أفلا يستطيع هؤلاء أن يأتوا بمثل القرآن؟ | H12: إعجاز القرآن. | القول بالصرفة. | القرآن تحدى بلغاء العرب. | I12: صاحب هذا السؤال يرى أن القرآن قد تحدى البشر أن يأتوا بمثله، والبلغاء والشعراء لهم كلام غاية في البلاغة؛ فهم يستطيعون أن يأتوا بمثله. | J12: إن كلام البلغاء والشعراء فيه كثير من أوجه البلاغة، ولكنه مهما بلغ في البلاغة مبلغا بعيدا، إلا أنه ورد عليه الكثير من «النقد والنقض»؛ فمثلا: المتنبي - وهو من هو بلاغة وفصاحة - قد صنفت المصنفات في نقد شعره؛ بل هناك باب كبير متخصص يعرف بـ «النقد الأدبي»، وله أقسام في الجامعات. أما القرآن، فهو كلام معجز إلى قيام الساعة، وقد تحدى الله به الثقلين «الإنس والجن»، وكان العرب أهل بلاغة وبيان، ومع هذا لم يستطيعوا معارضته، أو الإتيان بمثله، مع قوة المقتضي «العداوة والتحدي»؛ فهم أهل البلاغة والبيان، والقرآن يتحداهم في الليل والنهار، بل في الحاضر والمستقبل؛ فقال تعالى: ﴿فإن لم تفعلوا ولن تفعلوا﴾ [البقرة: 24]، فإذا كان القرآن كذلك، فلا مقارنة بينه وبين كلام البشر؛ قال تعالى: ﴿لا يأتيه الباطل من بين يديه ولا من خلفه تنزيل من حكيم حميد﴾ [فصلت: 42]. ثم إن إعجاز القرآن ليس قاصرا على بلاغته وبيانه، بل له أوجه كثيرة من الإعجاز؛ فهو معجز في لفظه ونظمه، وتراكيبه وبلاغته، معجز في معانيه، معجز في إخباره بالمغيبات، سواء فيما مضى، أو فيما يستقبل؛ فما أخبر به، فإنه يقع على وجهه دون اختلاف، معجز في تشريعه، معجز في تأثيره على النفوس، وغير ذلك الكثير من وجوه إعجازه؛ فهل في كلام البلغاء ما يجمع كل هذا؟! والجواب: أنه ليس في كلام أبلغ البلغاء، وأفصح الفصحاء: ما يساوي القرآن، أو يدانيه؛ ولهذا أقر العرب أنفسهم بأن القرآن لا يشبه كلام البشر. | K12: يبين أن القرآن تحدى العرب أن يأتوا بمثله فعجزوا مع بلاغتهم وعداوتهم، وأن إعجازه يشمل لفظه ومعانيه وأخباره وتشريعه. | L12: ما معنى أن القرآن معجز؟ | هل يستطيع أحد أن يأتي بمثل القرآن؟ | ما هو تحدي القرآن؟ | M12: ب | N12: نعم | O12: البقرة 24 (جزء)؛ فصلت 42 — نُسخت من المطبوع بالرسم الإملائي، ويجب استبدالها بنص مصحف مجمع الملك فهد | P12: محمد — 2026-10-04 | Q12: موافق | R12: مراجعة النقل: مطابق دون ملاحظات. مقطع حساس: وافق المختص الأعلم دون تعديل (2026-10-04). «لا يُجتزأ»: مقطع حجاجي يُعرض كاملاً حتى لا تُقتطع نتيجة دون حجتها (ملاحظة اللجنة). | S12: =IF(A12="","",IF(OR(M12="ج",M12="د"),"المستوى لا يُنشر",IF(IFERROR(INDEX(المصادر!$F$2:$F$30,MATCH(D12,المصادر!$A$2:$A$30,0)),"")<>"نعم","المصدر غير معتمد",IF(OR(B12="",E12="",J12="",K12="",P12=""),"بيانات ناقصة",IF(AND(N12="نعم",Q12<>"موافق"),"ينقصه رأي المختص","صالح للنشر"))))) | T12: نعم | U12: ما تعريف القرآن؟ | لماذا يعظّم المسلمون القرآن؟ | ما أمثلة الإعجاز العلمي؟
A13: ق-24 | B13: ح7 | C13: أساسي | D13: م-01 | E13: المسألة (27)، ص135–ص135 — مختصر الإجابة | F13: ادعاء أن القرآن مصدره البشر. | G13: لماذا لا يكون القرآن من وضع البشر، أو يكون من تأليف النبي ﷺ نفسه، وقد جاءت آية في القرآن تنص على ذلك: ﴿إنه لقول رسول كريم﴾ [الحاقة: 40]؟ | H13: مصدر القرآن الكريم. | القرآن كلام الله. | I13: حول مصدر القرآن، وادعاء بعض المشككين: أنه يمكن أن يكون مصدر القرآن بشرا. | J13: 1) عقلاء المشركين - من أهل الكتاب ومن غيرهم - يعلمون أن اليهود أو النصارى - وهم أهل كتاب كذلك - لا يمكن أن يكونوا مصدرا للقرآن الكريم؛ فقد كانوا أحرص الناس على معارضته. 2) وجود الإعجاز التاريخي، والتشريعي، والبلاغي والعلمي، وغير ذلك من الأمور التي لا يمكن أن يأتي بها بشر في ذلك الزمان -: ينقض هذا الادعاء. 3) ورود عتاب للنبي ﷺ في بعض الآيات -: يخالف هذه الدعوى. 4) عدم وجود أي اختلاف أو خطأ في القرآن الكريم، مع عجز العالمين عن الإتيان ولو بسورة من مثله -: يدل على أنه لا يمكن أن يأتي من عند بشر. | K13: يذكر أربعة أدلة مختصرة على أن القرآن ليس من تأليف بشر، منها ورود عتاب للنبي ﷺ في بعض الآيات. | L13: هل ألّف النبي القرآن؟ | لماذا لا يكون القرآن من كلام محمد؟ | كيف نعرف أن القرآن ليس من البشر؟ | M13: ب | N13: نعم | O13: لا يوجد في المقطع (آية الحاقة 40 في نص السؤال فقط); آية في السؤال المصدري | P13: محمد — 2026-10-04 | Q13: موافق | R13: مراجعة النقل: مطابق دون ملاحظات. مقطع حساس: وافق المختص الأعلم دون تعديل (2026-10-04). «لا يُجتزأ»: مقطع حجاجي يُعرض كاملاً حتى لا تُقتطع نتيجة دون حجتها (ملاحظة اللجنة). | S13: =IF(A13="","",IF(OR(M13="ج",M13="د"),"المستوى لا يُنشر",IF(IFERROR(INDEX(المصادر!$F$2:$F$30,MATCH(D13,المصادر!$A$2:$A$30,0)),"")<>"نعم","المصدر غير معتمد",IF(OR(B13="",E13="",J13="",K13="",P13=""),"بيانات ناقصة",IF(AND(N13="نعم",Q13<>"موافق"),"ينقصه رأي المختص","صالح للنشر"))))) | T13: نعم | U13: ما هو القرآن؟ | ما مكانة القرآن؟ | كيف كان الوحي ينزل؟
A14: ق-25 | B14: ح7 | C14: إضافي | D14: م-01 | E14: المسألة (25)، ص126–ص127 — مختصر الإجابة | F14: ادعاء أن القرآن مصدره الكتب السابقة. | G14: مصدر القرآن لم يكن وحيا من الله تعالى، بل هو مقتبس من الكتب السابقة. | H14: مصدر القرآن الكريم. | القرآن كلام الله. | الكتب السابقة. | I14: حول مصدر القرآن وعلاقته بالكتب السابقة؛ من حيث المضمون والأسلوب. | J14: 1) الاقتباس هو: «نقل فكرة معينة، بشكل كامل أو جزئي؛ بحيث لا يزيد المقتبس شيئا»، وفي حالة إضافة المقتبس أو تعديله للأفكار التي ينقلها، أو تصحيحه لها، فإن ذلك ينفي عن فعله صفة الاقتباس؛ ومعنى الاقتباس هذا لا يمكن أن ينطبق بأي حال من الأحوال على القرآن الكريم. 2) القرآن الكريم مختلف ومتميز عن الكتب السابقة في المضمون والأسلوب؛ وهذا ينفي الدعوى الواردة في السؤال؛ فأسلوب القصص في القرآن يتميز عن غيره من كتب العهد القديم، وأي إنسان يطلع على تلك القصص يدرك بسهولة: أن هناك بونا شاسعا في القصص بين كليهما. | K14: يعرّف الاقتباس ويبين أنه لا ينطبق على القرآن، لأنه يختلف عن الكتب السابقة في مضمونه وأسلوبه. | L14: هل نقل محمد القرآن من التوراة والإنجيل؟ | لماذا تتشابه قصص القرآن مع الكتب السابقة؟ | هل القرآن مقتبس؟ | M14: ب | N14: نعم | O14: — | P14: محمد — 2026-10-04 | Q14: موافق | R14: مراجعة النقل: مطابق دون ملاحظات. مقطع حساس: وافق المختص الأعلم دون تعديل (2026-10-04). «لا يُجتزأ»: مقطع حجاجي يُعرض كاملاً حتى لا تُقتطع نتيجة دون حجتها (ملاحظة اللجنة). | S14: =IF(A14="","",IF(OR(M14="ج",M14="د"),"المستوى لا يُنشر",IF(IFERROR(INDEX(المصادر!$F$2:$F$30,MATCH(D14,المصادر!$A$2:$A$30,0)),"")<>"نعم","المصدر غير معتمد",IF(OR(B14="",E14="",J14="",K14="",P14=""),"بيانات ناقصة",IF(AND(N14="نعم",Q14<>"موافق"),"ينقصه رأي المختص","صالح للنشر"))))) | T14: نعم | U14: ما معنى أن القرآن مهيمن على الكتب السابقة؟ | ما قصص الأنبياء في القرآن؟
A15: ق-26 | B15: ح7 | C15: إضافي | D15: م-01 | E15: المسألة (26)، ص131–ص131 — مختصر الإجابة | F15: ادعاء أن القرآن وثيقة قديمة. | G15: يقال: إن محمدا وجد وثيقة قديمة، فقام بتعديلها، ثم سماها قرآنا. | H15: مصدر القرآن الكريم. | القرآن كلام الله. | الكتب السابقة. | I15: يدور السؤال حول مصدر القرآن، وادعاء كون أصله وثيقة سابقة وجدها النبي ﷺ، فقام بتعديلها، وسماها قرآنا. | J15: القول بأن القرآن وثيقة قديمة، ولم يجدها سوى النبي الأمي محمد ﷺ، دون سائر البشر، هو: مجرد افتراء، تنقضه الشواهد الكثيرة؛ بتوافق القرآن مع أسباب النزول، وكذلك: انتظار النبي ﷺ للوحي في بعض الأحيان كي يأتيه بجواب؛ مثل انتظاره للوحي في حادثة الإفك، وكذلك: كيف يتأتى لإنسان يحمل وثيقة قديمة أن ينكشف له غيب المستقبل؛ فيخبر بأمور غيبية، وهو واثق كل الثقة في حدوثها، وقد تحقق فعلا ما تنبأ به؛ كبعض الحقائق العلمية، وغيرها، وكذلك: فالحجة قائمة بالبينات التي في القرآن الكريم؛ وكل هذا يدل على أن مصدر هذا القرآن ليس بشريا على الإطلاق. | K15: يرد على القول بأن القرآن وثيقة قديمة، بتوافقه مع أسباب النزول، وانتظار النبي ﷺ الوحي أحيانا، وإخباره بأمور مستقبلية تحققت. | L15: هل وجد النبي القرآن مكتوبا؟ | هل كان النبي ينتظر الوحي؟ | M15: ب | N15: نعم | O15: يشير إلى حادثة الإفك دون نص | P15: محمد — 2026-10-04 | Q15: موافق | R15: مراجعة النقل: مطابق دون ملاحظات. مقطع حساس: وافق المختص الأعلم دون تعديل (2026-10-04). «لا يُجتزأ»: مقطع حجاجي يُعرض كاملاً حتى لا تُقتطع نتيجة دون حجتها (ملاحظة اللجنة). | S15: =IF(A15="","",IF(OR(M15="ج",M15="د"),"المستوى لا يُنشر",IF(IFERROR(INDEX(المصادر!$F$2:$F$30,MATCH(D15,المصادر!$A$2:$A$30,0)),"")<>"نعم","المصدر غير معتمد",IF(OR(B15="",E15="",J15="",K15="",P15=""),"بيانات ناقصة",IF(AND(N15="نعم",Q15<>"موافق"),"ينقصه رأي المختص","صالح للنشر"))))) | T15: نعم | U15: كيف جُمع القرآن؟ | ما أسباب نزول آية بعينها؟
A16: ق-27 | B16: ح7 | C16: إضافي | D16: م-01 | E16: المسألة (29)، ص143–ص143 — مختصر الإجابة | F16: ادعاء الاستطاعة بإيجاد مثل علوم القرآن ومعارفه لبعض النابغين ذوي المواهب من الناس. | G16: هل يصح القول بأن ما في القرآن من علوم ومعارف ما هي إلا آثار لمواهب بعض النابغين من الناس، وهذه المواهب وآثارها وجدت، ويمكن أن توجد في كل أمة؟ | H16: هل يمكن للنابغين والموهوبين الإتيان بمثل ما في القرآن من علوم ومعارف؟ | I16: — | J16: ينقض هذا الادعاء: وجود الإعجاز التاريخي، والتشريعي، والبلاغي، والعلمي، وغير ذلك من الأمور التي لا يمكن أن يأتي بها بشر في ذلك الزمان، وفي الأزمنة بعده. وإن ذكاء البشر مهما وصل، ومواهب النابغين مهما بلغت، تختلف تمام الاختلاف عن المعجزات، التي هي من خصائص الربوبية، وليست في قدرة أحد من البشر أو الخلق. كما اشتمل القرآن على علوم ومعارف تهدي البشر إلى طريق الحق والصواب، والسعادة في جميع شؤونهم في حياتهم الدنيا والآخرة، وتجنبهم الشر بحذافيره، في كل زمان ومكان؛ وهذه العلوم والمعارف ليست في مقدور الخلق. | K16: يبين أن ذكاء البشر ومواهبهم مهما بلغت لا تصل إلى ما في القرآن من إعجاز وعلوم تهدي إلى الحق. | L16: ألا يمكن أن يكون القرآن من عبقري؟ | هل يستطيع شخص ذكي أن يكتب مثل القرآن؟ | M16: ب | N16: نعم | O16: لا يوجد في الفقرات المختارة | P16: محمد — 2026-10-04 | Q16: موافق | R16: مراجعة النقل: مطابق دون ملاحظات. مقطع حساس: وافق المختص الأعلم دون تعديل (2026-10-04). «لا يُجتزأ»: مقطع حجاجي يُعرض كاملاً حتى لا تُقتطع نتيجة دون حجتها (ملاحظة اللجنة). | S16: =IF(A16="","",IF(OR(M16="ج",M16="د"),"المستوى لا يُنشر",IF(IFERROR(INDEX(المصادر!$F$2:$F$30,MATCH(D16,المصادر!$A$2:$A$30,0)),"")<>"نعم","المصدر غير معتمد",IF(OR(B16="",E16="",J16="",K16="",P16=""),"بيانات ناقصة",IF(AND(N16="نعم",Q16<>"موافق"),"ينقصه رأي المختص","صالح للنشر"))))) | T16: نعم | U16: ما أمثلة الإعجاز العلمي؟ | ما مكانة القرآن؟
A17: ق-01 | B17: ح1 | C17: أساسي | D17: م-02 | E17: المبحث الثاني: تعريف القرآن اصطلاحاً، الفقرة الأولى — https://dorar.net/aqeeda/1365 | I17: — | J17: القُرْآنُ الكريمُ هو اسمٌ لكلامِ اللهِ تعالى وكِتابِه، المنَزَّلُ على عَبدِه ورَسولِه مُحَمَّدٍ صلَّى اللهُ عليه وسلَّم بواسِطةِ جِبريلَ عليه السَّلامُ بلِسانٍ عَربيٍّ مُبِينٍ، المنقولُ إلينا بالتواتُرِ، المكتوبُ في المُصحَفِ، المتعَبَّدُ بتلاوتِه، المبدوءُ بسُورةِ الفاتحةِ، والمختومُ بسُورةِ النَّاسِ، والمُعجِزُ بأقصَرِ سُوَرِه . | K17: ما القرآن؟ تعريفه: كلام الله المنزل على محمد ﷺ بواسطة جبريل، بلسان عربي، المنقول بالتواتر، المكتوب في المصحف، المتعبد بتلاوته. | L17: ما هو القرآن؟ | ما تعريف القرآن؟ | إيش يعني القرآن؟ | من أين جاء القرآن؟ | M17: أ | N17: لا | O17: — | P17: محمد — 5 أكتوبر 2026 | R17: اعتُمد دون ملاحظات. | S17: =IF(A17="","",IF(OR(M17="ج",M17="د"),"المستوى لا يُنشر",IF(IFERROR(INDEX(المصادر!$F$2:$F$30,MATCH(D17,المصادر!$A$2:$A$30,0)),"")<>"نعم","المصدر غير معتمد",IF(OR(B17="",E17="",J17="",K17="",P17=""),"بيانات ناقصة",IF(AND(N17="نعم",Q17<>"موافق"),"ينقصه رأي المختص","صالح للنشر"))))) | U17: لماذا يعظّم المسلمون القرآن؟ | هل القرآن من تأليف محمد؟ | ما معنى كلمة قرآن في اللغة؟
A18: ق-02 | B18: ح1 | C18: أساسي | D18: م-02 | E18: فضائل القرآن — المبحث الأول: من فضائل القرآن أنه هدى للمتقين — https://dorar.net/aqeeda/1376 | I18: — | J18: قال اللهُ تعالى: ﴿ذَلِكَ الكِتَابُ لَا رَيْبَ فِيهِ هُدًى لِلْمُتَّقِينَ﴾ [البقرة: 2] . […] وقال اللهُ عَزَّ وجَلَّ: ﴿إِنَّ هَذَا القُرْآنَ يَهْدِي لِلَّتِي هِيَ أَقْوَمُ﴾ [الإسراء: 9] . قال السَّعديُّ: (يخبرُ تعالى عن شَرَفِ القُرْآنِ وجَلالتِه وأنَّه يَهْدِي لِلَّتِي هِيَ أَقْوَمُ أي: أعدَلُ وأعلى من العقائدِ والأعمالِ والأخلاقِ، فمن اهتدى بما يدعو إليه القُرْآنُ كان أكمَلَ النَّاسِ وأقوَمَهم وأهداهم في جميعِ أُمورِه) | K18: مكانة القرآن: أنه هدى للمتقين، ويهدي للتي هي أقوم في العقائد والأعمال والأخلاق. | L18: ما مكانة القرآن عند المسلمين؟ | لماذا يعظّم المسلمون القرآن؟ | ما فائدة القرآن للإنسان؟ | لماذا يقرأ المسلمون القرآن كثيراً؟ | M18: أ | N18: لا | O18: البقرة 2؛ الإسراء 9 (تُعرض من المصحف). في كلام السعدي جزء آية دون علامة. | P18: محمد — 5 أكتوبر 2026 | R18: اعتُمد دون ملاحظات. | S18: =IF(A18="","",IF(OR(M18="ج",M18="د"),"المستوى لا يُنشر",IF(IFERROR(INDEX(المصادر!$F$2:$F$30,MATCH(D18,المصادر!$A$2:$A$30,0)),"")<>"نعم","المصدر غير معتمد",IF(OR(B18="",E18="",J18="",K18="",P18=""),"بيانات ناقصة",IF(AND(N18="نعم",Q18<>"موافق"),"ينقصه رأي المختص","صالح للنشر"))))) | U18: ما تعريف القرآن؟ | ما فضل قراءة القرآن؟
A19: ق-03 | B19: ح1 | C19: أساسي | D19: م-02 | E19: خصائص القرآن — المبحث الثامن: هيمنته على الكتب السابقة — https://dorar.net/aqeeda/1417 | I19: — | J19: قال اللهُ تعالى: ﴿وَأَنْزَلْنَا إِلَيْكَ الْكِتَابَ بِالْحَقِّ مُصَدِّقًا لِمَا بَيْنَ يَدَيْهِ مِنَ الْكِتَابِ وَمُهَيْمِنًا عَلَيْهِ فَاحْكُمْ بَيْنَهم بِمَا أَنْزَلَ اللَّهُ﴾ [المائدة: 48] . أي: وأنزلْناه شاهدًا للكتُبِ الإلهيَّةِ السَّابقةِ بصِدقها، وموافقًا لها، ومطابِقًا لأخبارِها وأصولِ شرائِعِها، وفي وجودِه أيضًا دَلالةٌ على صِدقِها؛ لأنَّها أَخبرتْ بنُزولِ القُرآنِ. وأنزلْناه أمينًا على الكتُبِ الإلهيَّةِ السَّابقةِ، حافظًا لها، مُشتَمِلًا على ما اشتملَتْ عليه الكتُبُ السَّابقَةُ وزيادةٍ، وناسِخًا لها، وحاكمًا عليها كلِّها، فما شهِد له القُرْآنُ منها بالصِّدقِ فهو مقبولٌ، وما شهِد له بالردِّ فهو مردودٌ، قد دخلَه التحريفُ والتبديلُ، وإلَّا فلو كان مِن عِندِ اللهِ تعالى لم يُخالِفْه. وما دام أنَّ هذه هي حالُ القُرْآنِ؛ فاحكُمْ إذنْ -يا محمَّدُ- بينَ أهلِ الكِتاب وغيرِهم بهذا القُرْآنِ العظيمِ في كلِّ ما احتَكموا فيه إليك . […] وقال ابنُ كثيرٍ: (جعل اللهُ هذا الكِتابَ العظيمَ الذي أنزله آخِرَ الكُتُبِ وخاتِمَها وأشمَلَها وأعظَمَها وأكمَلَها؛ حيث جمع فيه محاسِنَ ما قَبْلَه وزاده من الكمالاتِ ما ليس في غيرِه؛ فلهذا جعله شاهدًا وأمينًا، وحاكمًا عليها كُلِّها) . | K19: صلة القرآن بالكتب السابقة: مصدّق لها ومهيمن عليها، أمين وشاهد وحاكم عليها، وهو آخر الكتب وخاتمها. | L19: هل القرآن مثل الإنجيل عند المسيحيين؟ | ما علاقة القرآن بالتوراة والإنجيل؟ | ما معنى أن القرآن مهيمن؟ | M19: ب | N19: نعم | O19: المائدة 48 (تُعرض من المصحف) | P19: محمد — 5 أكتوبر 2026 | Q19: موافق | R19: نُفّذ: تُعرض الآية وشرحها كاملين، وقول ابن كثير عند «أريد التفصيل» فقط. مقطع حساس: وافق المختص الأعلم. | S19: =IF(A19="","",IF(OR(M19="ج",M19="د"),"المستوى لا يُنشر",IF(IFERROR(INDEX(المصادر!$F$2:$F$30,MATCH(D19,المصادر!$A$2:$A$30,0)),"")<>"نعم","المصدر غير معتمد",IF(OR(B19="",E19="",J19="",K19="",P19=""),"بيانات ناقصة",IF(AND(N19="نعم",Q19<>"موافق"),"ينقصه رأي المختص","صالح للنشر"))))) | T19: نعم | U19: هل نقل محمد القرآن من التوراة؟ | ما الفرق بين القرآن والحديث؟ | V19: وقال ابنُ كثيرٍ: (جعل اللهُ هذا الكِتابَ العظيمَ الذي أنزله آخِرَ الكُتُبِ وخاتِمَها وأشمَلَها وأعظَمَها وأكمَلَها؛ حيث جمع فيه محاسِنَ ما قَبْلَه وزاده من الكمالاتِ ما ليس في غيرِه؛ فلهذا جعله شاهدًا وأمينًا، وحاكمًا عليها كُلِّها) .
A20: ق-34 | B20: ح1 | C20: إضافي | D20: م-02 | E20: المبحث الأول: تعريف القرآن لغةً — https://dorar.net/aqeeda/1363 | I20: — | J20: القُرآنُ في الأصلِ مَصدَرٌ، يقالُ: قَرَأَ يَقْرَأُ قِراءةً وقُرْآنًا، ثمَّ أُطلِقَ على المقروءِ، وسُمِّي القُرآنُ قُرآنًا؛ لأنَّه يجمَعُ السُّوَرَ فيَضُمُّها، وكُلُّ شَيءٍ جَمَعْتَه فقد قرَأْتَه، وأصلُ (قرأ): يَدُلُّ على جَمعٍ واجْتِماعٍ | K20: معنى كلمة «قرآن» في اللغة، ولماذا سُمّي القرآن بهذا الاسم. | L20: ما معنى كلمة قرآن؟ | لماذا سمي القرآن قرآناً؟ | M20: أ | N20: لا | O20: — | P20: محمد — 5 أكتوبر 2026 | R20: اعتُمد دون ملاحظات. | S20: =IF(A20="","",IF(OR(M20="ج",M20="د"),"المستوى لا يُنشر",IF(IFERROR(INDEX(المصادر!$F$2:$F$30,MATCH(D20,المصادر!$A$2:$A$30,0)),"")<>"نعم","المصدر غير معتمد",IF(OR(B20="",E20="",J20="",K20="",P20=""),"بيانات ناقصة",IF(AND(N20="نعم",Q20<>"موافق"),"ينقصه رأي المختص","صالح للنشر"))))) | U20: ما تعريف القرآن اصطلاحاً؟ | ما أسماء القرآن الأخرى؟
A21: ق-35 | B21: ح1 | C21: إضافي | D21: م-02 | E21: المبحث الثاني: الفرق بين القرآن الكريم والحديث القدسي، الفروق 1–4 من 13 — https://dorar.net/aqeeda/1365 | I21: — | J21: 1- أنَّ القُرْآنَ الكريمَ تحدَّى اللهُ النَّاسَ أن يأتُوا بمِثْلِه، أو بعَشْرِ سُوَرٍ مِثْلِه، أو بسُورةٍ مِن مِثْلِه، أو بحديثٍ مِثْلِه؛ فعَجَزوا. أمَّا الحديثُ القُدُسيُّ فلم يقَعْ به التحَدِّي والإعجازُ. 2- أنَّ القُرْآنَ الكريمَ منقولٌ بطريقِ التواتُرِ، فهو قَطعيُّ الثُّبوتِ كُلُّه؛ سُوَرُه وآياتُه، وجُمَلُه ومُفرداتُه، وحُروفُه وحَرَكاتُه وسَكَناتُه، أمَّا الحديثُ القُدُسيُّ فأغلَبُه أحاديثُ آحادٍ ظَنِّيُّ الثُّبوتِ. 3- أنَّ القُرْآنَ الكريمَ مِن عِندِ اللهِ لفظًا ومعنًى، أمَّا الحديثُ القُدُسيُّ فمعناه من اللهِ باتِّفاقِ العُلَماءِ، أمَّا لَفظُه فاختُلِف فيه. 4- أنَّ القُرْآنَ الكريمَ لا يُنسَبُ إلَّا إلى اللهِ تعالى، أمَّا الحديثُ القُدُسيُّ فيُنسَبُ إلى اللهِ تعالى نسبةَ إنشاءٍ، فيُقالُ: قال اللهُ تعالى، ويُروى مضافًا إلى الرَّسولِ الله صلَّى اللهُ عليه وسلَّم نِسبةَ إخبارٍ، فيُقالُ: قال رَسولُ اللهِ صلَّى اللهُ عليه وسلَّم فيما يرويه عن رَبِّه. | K21: الفرق بين القرآن الكريم والحديث القدسي: التحدي بالقرآن، وتواتره، وأنه من الله لفظاً ومعنى، ونسبته إلى الله. | L21: ما الفرق بين القرآن والحديث القدسي؟ | هل الحديث القدسي من القرآن؟ | هل الحديث القدسي كلام الله مثل القرآن؟ | M21: ب | N21: لا | O21: — | P21: محمد — 5 أكتوبر 2026 | R21: نُفّذ: البند الثاني لا يظهر إلا عند «أريد التفصيل». | S21: =IF(A21="","",IF(OR(M21="ج",M21="د"),"المستوى لا يُنشر",IF(IFERROR(INDEX(المصادر!$F$2:$F$30,MATCH(D21,المصادر!$A$2:$A$30,0)),"")<>"نعم","المصدر غير معتمد",IF(OR(B21="",E21="",J21="",K21="",P21=""),"بيانات ناقصة",IF(AND(N21="نعم",Q21<>"موافق"),"ينقصه رأي المختص","صالح للنشر"))))) | U21: هل السنة حجة؟ | ما تعريف القرآن؟ | ما الفرق بين القرآن والحديث النبوي؟ | V21: 2- أنَّ القُرْآنَ الكريمَ منقولٌ بطريقِ التواتُرِ، فهو قَطعيُّ الثُّبوتِ كُلُّه؛ سُوَرُه وآياتُه، وجُمَلُه ومُفرداتُه، وحُروفُه وحَرَكاتُه وسَكَناتُه، أمَّا الحديثُ القُدُسيُّ فأغلَبُه أحاديثُ آحادٍ ظَنِّيُّ الثُّبوتِ.
A22: ق-08 | B22: ح2 | C22: أساسي | D22: م-03 | E22: الفصل 2: الوحي — كيفية وحي الملك إلى الرسول (ص 33–35) — https://www.islamweb.net/ar/library/content/246/10/ | F22: كيفية وحي الملك إلى الرسول | I22: — | J22: وحي الله إلى أنبيائه إما أن يكون بغير واسطة […] وكان منه الرؤيا الصالحة في المنام، والكلام الإلهي من وراء حجاب يقظة، وإما أن يكون بواسطة ملك الوحي وهو الذي يعنينا في هذا الموضوع لأن القرآن الكريم نزل به. ولا تخلو كيفية وحي الملك إلى الرسول من إحدى حالتين: الحالة الأولى: وهي أشد على الرسول، أن يأتيه مثل صلصلة الجرس، والصوت القوي يثير عوامل الانتباه فتهيأ النفس بكل قواها لقبول أثره، فإذا نزل الوحي بهذه الصورة على الرسول -صلى الله عليه وسلم- نزل عليه وهو مستجمع القوى الإدراكية لتلقيه وحفظه وفهمه، وقد يكون هذا الصوت حفيف أجنحة الملائكة وقد يكون صوت الملك نفسه في أول سماع الرسول له. والحالة الثانية: أن يتمثل له الملك رجلا ويأتيه في صورة بشر، وهذه الحالة أخف من سابقتها، حيث يكون التناسب بين المتكلم والسامع، ويأنس رسول النبوة عند سماعه من رسول الوحي، ويطمئن إليه اطمئنان الإنسان لأخيه الإنسان. […] وكلتا الحالتين مذكور فيما روي عن عائشة أم المؤمنين -رضي الله عنها- أن الحارث بن هشام رضي الله عنه سأل رسول الله -صلى الله عليه وسلم- فقال: "يا رسول الله.. كيف يأتيك الوحي؟ فقال رسول الله صلى الله عليه وسلم: أحيانا يأتيني مثل صلصلة الجرس، وهو أشد علي، فيفصم عني وقد وعيت عنه ما قال، وأحيانا يتمثل لي الملك رجلا فيكلمني فأعي ما يقول". وروت عائشة رضي الله عنها ما كان يصيب رسول الله -صلى الله عليه وسلم- من شدة فقالت: "ولقد رأيته ينزل عليه الوحي في اليوم الشديد البرد فيفصم عنه وإن جبينه ليتفصد عرقا". […] | K22: كيف كان الوحي يأتي النبي ﷺ: وحي الله إلى أنبيائه يكون بالرؤيا الصالحة أو بالكلام من وراء حجاب أو بواسطة الملك، والقرآن نزل بواسطة الملك، إما مثل صلصلة الجرس وهو أشدّ، وإما أن يتمثّل له الملك رجلاً. | L22: كيف كان الوحي يأتي النبي؟ | ما هو الوحي؟ | كيف وصل القرآن لمحمد؟ | كيف كان جبريل ينزل بالقرآن؟ | ما طرق نزول الوحي على النبي؟ | هل كان جبريل يأتي النبي في صورة رجل؟ | ما معنى أن الوحي كان مثل صلصلة الجرس؟ | هل كان نزول الوحي شديداً على النبي؟ | هل نزل القرآن على النبي في المنام؟ | M22: أ | N22: لا | O22: حديث عائشة في سؤال الحارث بن هشام، وقولها «ولقد رأيته ينزل عليه الوحي في اليوم الشديد البرد…»: صحيح البخاري (2)، وصحيح مسلم (2333). | P22: محمد — 5 أكتوبر 2026 | R22: نُفّذ: كل طرق الوحي من القطان، والأحاديث عند «أريد التفصيل»، وصياغات لكل طريقة. | S22: =IF(A22="","",IF(OR(M22="ج",M22="د"),"المستوى لا يُنشر",IF(IFERROR(INDEX(المصادر!$F$2:$F$30,MATCH(D22,المصادر!$A$2:$A$30,0)),"")<>"نعم","المصدر غير معتمد",IF(OR(B22="",E22="",J22="",K22="",P22=""),"بيانات ناقصة",IF(AND(N22="نعم",Q22<>"موافق"),"ينقصه رأي المختص","صالح للنشر"))))) | U22: في أي شهر نزل القرآن؟ | لماذا لم ير الناس جبريل؟ | هل نزل القرآن مرة واحدة؟ | V22: وكلتا الحالتين مذكور فيما روي عن عائشة أم المؤمنين -رضي الله عنها- أن الحارث بن هشام رضي الله عنه سأل رسول الله -صلى الله عليه وسلم- فقال: "يا رسول الله.. كيف يأتيك الوحي؟ فقال رسول الله صلى الله عليه وسلم: أحيانا يأتيني مثل صلصلة الجرس، وهو أشد علي، فيفصم عني وقد وعيت عنه ما قال، وأحيانا يتمثل لي الملك رجلا فيكلمني فأعي ما يقول". | وروت عائشة رضي الله عنها ما كان يصيب رسول الله -صلى الله عليه وسلم- من شدة فقالت: "ولقد رأيته ينزل عليه الوحي في اليوم الشديد البرد فيفصم عنه وإن جبينه ليتفصد عرقا".
A23: ق-09 | B23: ح2 | C23: أساسي | D23: م-02 | E23: فضائل القرآن — المبحث الثاني: إنزاله في شهر رمضان، أول المبحث — https://dorar.net/aqeeda/1378 | I23: — | J23: إذا كان شَهرُ رَمَضانَ قد نال هذه المزِيَّةَ بسبب نزول القُرْآنِ فيه، فما الظَّنُّ بشَرَفِ القُرْآنِ المنَزَّلِ نفسِه؟! قال اللهُ سُبحانَه: ﴿شَهْرُ رَمَضَانَ الَّذِي أُنْزِلَ فِيهِ القُرْآَنُ هُدًى لِلنَّاسِ وَبَيِّنَاتٍ مِنَ الهُدَى وَالفُرْقَانِ﴾ [البقرة: 185] . قال البقاعيُّ: (في مَدْحِه بإنزالِه فيه مَدحٌ للقُرْآنِ به) . | K23: متى نزل القرآن: نزل في شهر رمضان، وصار نزوله فيه مزيّة لهذا الشهر. | L23: متى نزل القرآن؟ | في أي شهر نزل القرآن؟ | ما علاقة القرآن برمضان؟ | M23: أ | N23: لا | O23: البقرة 185 (تُعرض من المصحف) | P23: محمد — 5 أكتوبر 2026 | R23: اعتُمد دون ملاحظات. | S23: =IF(A23="","",IF(OR(M23="ج",M23="د"),"المستوى لا يُنشر",IF(IFERROR(INDEX(المصادر!$F$2:$F$30,MATCH(D23,المصادر!$A$2:$A$30,0)),"")<>"نعم","المصدر غير معتمد",IF(OR(B23="",E23="",J23="",K23="",P23=""),"بيانات ناقصة",IF(AND(N23="نعم",Q23<>"موافق"),"ينقصه رأي المختص","صالح للنشر"))))) | U23: كيف كان الوحي يأتي النبي؟ | هل نزل القرآن مرة واحدة؟ | ما فضل شهر رمضان؟
A24: ق-37 | B24: ح2 | C24: إضافي | D24: م-02 | E24: خصائص القرآن — المبحث الثامن، من كلام ابن كثير في نزول القرآن منجّماً — https://dorar.net/aqeeda/1417 | I24: — | J24: [قال ابن كثير:] (… القُرْآنِ الذي شرَّفه اللهُ على كُلِّ كِتابٍ أنزله، وجعله مُهَيمِنًا عليه وناسِخًا له وخاتمًا له؛ لأنَّ كُلَّ الكُتُبِ المتقَدِّمةِ نزلت إلى الأرضِ جملةً واحدةً، وهذا القُرْآنُ نزل مُنجَّمًا بحسَبِ الوقائِعِ؛ لشِدَّةِ الاعتناءِ به وبمن أُنزِل عليه، فكُلُّ مرَّةٍ كنُزولِ كِتابٍ مِن الكُتُبِ المتقَدِّمةِ) . | K24: نزول القرآن منجّماً (مفرّقاً) بحسب الوقائع، بخلاف الكتب السابقة التي نزلت جملة واحدة. | L24: هل نزل القرآن مرة واحدة؟ | لماذا نزل القرآن مفرّقاً؟ | كم مرة نزل القرآن؟ | M24: أ | N24: لا | O24: — | P24: محمد — 5 أكتوبر 2026 | R24: اعتُمد دون ملاحظات. | S24: =IF(A24="","",IF(OR(M24="ج",M24="د"),"المستوى لا يُنشر",IF(IFERROR(INDEX(المصادر!$F$2:$F$30,MATCH(D24,المصادر!$A$2:$A$30,0)),"")<>"نعم","المصدر غير معتمد",IF(OR(B24="",E24="",J24="",K24="",P24=""),"بيانات ناقصة",IF(AND(N24="نعم",Q24<>"موافق"),"ينقصه رأي المختص","صالح للنشر"))))) | U24: في أي شهر نزل القرآن؟ | كيف كان الوحي يأتي النبي؟
A25: ق-33 | B25: ح3 | C25: أساسي | D25: م-02 | E25: المطلب الثاني: حفظ القرآن في عهد الصحابة، كلام ابن عثيمين في مراحل الجمع (مع قصّ) — https://dorar.net/aqeeda/1413 | I25: — | J25: وقال ابنُ عُثَيمين: (لكِتابةِ القُرْآنِ وجمعِه ثلاثُ مَراحِلَ: المَرحلةُ الأُولى: في عَهدِ النَّبيِّ صلَّى اللهُ عليه وسلَّم، وكان الاعتمادُ في هذه المرحلةِ على الحِفظِ أكثَرَ من الاعتمادِ على الكِتابةِ؛ لقُوَّةِ الذَّاكِرةِ وسُرعةِ الِحفظِ، وقِلَّةِ الكاتِبينَ ووسائِلِ الكِتابةِ؛ ولذلك لم يُجمَعْ في مُصحَفٍ، بل كان من سمع آيةً حَفِظها، أو كتبها فيما تيسَّر له من عُسُبِ النَّخلِ، ورِقاعِ الجُلودِ، ولخافِ الحِجارةِ، وكِسَرِ الأكتافِ، وكان القُرَّاءُ عددًا كبيرًا. […] المَرحَلةُ الثَّانيةُ: في عَهدِ أبي بكرٍ رَضِيَ اللهُ عنه في السَّنةِ الثَّانيةَ عَشرةَ من الهِجرةِ. وسَبَبُه أنَّه قُتِل في وقعةِ اليمامةِ عَدَدٌ كبيرٌ مِن القُرَّاءِ؛ منهم سالمٌ مولى أبي حُذَيفةَ؛ أحدُ من أمر النَّبيُّ صلَّى اللهُ عليه وسلَّم بأخْذِ القُرْآنِ منهم . فأمر أبو بكرٍ رَضِيَ اللهُ عنه بجَمْعِه؛ لئلَّا يضيعَ... وقد وافق المُسلِمون أبا بكرٍ على ذلك وعدُّوه من حسَناتِه، حتى قال عليٌّ رَضِيَ اللهُ عنه: أعظَمُ النَّاسِ في المصاحِفِ أجرًا أبو بكرٍ، رحمةُ اللهِ على أبي بكرٍ؛ هو أوَّلُ من جمع كِتابَ اللهِ. المَرحَلةُ الثَّالِثُةُ: في عَهدِ أميرِ المُؤمِنين عثمانَ بنِ عَفَّانَ رَضِيَ اللهُ عنه في السَّنةِ الخامِسةِ والعِشرينَ. وسَبَبُه اختلافُ النَّاسِ في القراءةِ بحسَبِ اختلافِ الصُّحُفِ التي في أيدي الصَّحابةِ رَضِيَ اللهُ عنهم، فخِيفَت الفِتنةُ، فأمَرَ عُثمانُ رَضِيَ اللهُ عنه أن تُجمَعَ هذه الصُّحُفُ في مُصحَفٍ واحدٍ؛ لئلَّا يختَلِفَ النَّاسُ، فيتنازعوا في كِتابِ اللهِ تعالى ويتفَرَّقوا... وقد فعل عثمانُ رَضِيَ اللهُ عنه هذا بعد أن استشار الصَّحابةَ رَضِيَ اللهُ عنهم […] وقد بقي على ما كان عليه حتى الآن متَّفَقًا عليه بين المُسلِمين متواتِرًا بينهم، يتلقَّاه الصغيرُ عن الكبيرِ، لم تعبَثْ به أيدي المفسِدين، ولم تطمِسْه أهواءُ الزَّائغِين. فللَّهِ الحمدُ رَبِّ السَّمَواتِ ورَبِّ الأرضِ رَبِّ العالَمين) . | K25: مراحل جمع القرآن الثلاث: في عهد النبي ﷺ حفظاً وكتابة متفرقة، ثم في عهد أبي بكر، ثم في عهد عثمان رضي الله عنهما، وبقاؤه متواتراً إلى اليوم. | L25: كيف جُمع القرآن؟ | متى صار القرآن كتاباً واحداً؟ | لماذا جمع أبو بكر القرآن؟ | لماذا جمع عثمان القرآن؟ | هل تغيّر القرآن منذ زمن الصحابة؟ | M25: ب | N25: لا | O25: قول علي رضي الله عنه في فضل أبي بكر (أثر منقول في كلام ابن عثيمين) | P25: محمد — 5 أكتوبر 2026 | R25: اعتُمد دون ملاحظات. | S25: =IF(A25="","",IF(OR(M25="ج",M25="د"),"المستوى لا يُنشر",IF(IFERROR(INDEX(المصادر!$F$2:$F$30,MATCH(D25,المصادر!$A$2:$A$30,0)),"")<>"نعم","المصدر غير معتمد",IF(OR(B25="",E25="",J25="",K25="",P25=""),"بيانات ناقصة",IF(AND(N25="نعم",Q25<>"موافق"),"ينقصه رأي المختص","صالح للنشر"))))) | U25: كيف كان الوحي ينزل؟ | من رتّب سور القرآن؟
A26: ق-38 | B26: ح3 | C26: إضافي | D26: م-02 | E26: خصائص القرآن — المبحث السادس، المطلب الأول: حفظ القرآن في عهد النبوة، الوجهان 3 و6 — https://dorar.net/aqeeda/1411 | I26: — | J26: للحِفظِ في عَهدِ النُّبُوَّةِ عِدَّةُ أوجُهٍ؛ منها: […] 3- كِتابةُ الوَحيِ ومُقابلَتُه: قال الحارِثُ المحاسبيُّ: (كِتابةُ القُرْآنِ ليست مُحدَثةً؛ فإنَّه صلَّى اللهُ عليه وسلَّم كان يأمُرُ بكِتابتِه ولكِنَّه كان مُفَرَّقًا في الرِّقاعِ والأكتافِ والعُسُبِ ، وإنما أمر الصِّدِّيقُ بنَسْخِها من مكانٍ إلى مكانٍ، وكان ذلك بمَنْزِلةِ أوراقٍ وُجِدَت في بيتِ رَسولِ الله صلَّى اللهُ عليه وسلَّم فيها القُرْآنُ مُنتَشِرٌ، فجَمَعها جامِعٌ وربطَها بخَيطٍ حتى لا يَضِيعَ منها شَيءٌ) . وقال أبو عَمرٍو الدَّاني: (إنَّ رَسولَ اللهِ صلَّى اللهُ عليه وسلَّم سَنَّ جمعَ القُرْآنِ وكِتابتَه، وأمر بذلك وأملاه على كَتَبَتِه، وأنَّه صلَّى اللهُ عليه وسلَّم لم يَمُتْ حتى حَفِظَ جميعَ القُرْآنِ جماعةٌ من أصحابِه) . […] 6- قُوَّةُ الحافِظةِ عند العَرَبِ: كان العَرَبُ أهلَ حافِظةٍ لا تكادُ تُخطِئُ، وذاكِرةٍ لا يكادُ يَعزُبُ عنها شيءٌ، وخاصَّةً أنَّ القُرْآنَ جاء بأسلوبٍ بارعٍ، وبيانٍ رَفيعٍ؛ ممَّا جعله أحرى لحِفْظِه، والاهتمامِ به، حتى كَثُر آخِذوه صدرًا وسَطرًا. | K26: كيف حُفظ القرآن زمن النبي ﷺ: كان يأمر بكتابته فكُتب مفرّقاً في الرقاع والأكتاف، وحفظه جماعة من أصحابه، وكان العرب أهل حافظة قوية. | L26: كيف حُفظ القرآن زمن النبي؟ | هل كُتب القرآن في حياة النبي؟ | كيف استطاع الصحابة حفظ القرآن؟ | M26: أ | N26: لا | O26: — | P26: محمد — 5 أكتوبر 2026 | R26: اعتُمد دون ملاحظات. | S26: =IF(A26="","",IF(OR(M26="ج",M26="د"),"المستوى لا يُنشر",IF(IFERROR(INDEX(المصادر!$F$2:$F$30,MATCH(D26,المصادر!$A$2:$A$30,0)),"")<>"نعم","المصدر غير معتمد",IF(OR(B26="",E26="",J26="",K26="",P26=""),"بيانات ناقصة",IF(AND(N26="نعم",Q26<>"موافق"),"ينقصه رأي المختص","صالح للنشر"))))) | U26: لماذا جمع عثمان القرآن؟ | كم عدد حفّاظ القرآن اليوم؟
A27: ق-36 | B27: ح6 | C27: أساسي | D27: م-02 | E27: فضائل القرآن — المبحث الثامن: الوعد بالثواب على قراءته ومدارسته — https://dorar.net/aqeeda/1390 | I27: — | J27: عن أبي هُرَيرةَ رَضِيَ اللهُ عنه أنَّ رَسولَ اللهِ صلَّى اللهُ عليه وسلَّم قال: ((… وما اجتمع قومٌ في بيتٍ من بُيوتِ اللهِ يَتْلون كِتابَ اللهِ ويتدارسونَه بينهم، إلَّا نزلت عليهم السَّكينةُ، وغَشِيَتهم الرَّحمةُ، وحَفَّتْهم المَلائِكةُ، وذكرهم اللهُ فيمَن عِندَه )) . […] قال ابنُ عُثَيمين: (هذا القُرْآنُ له فضائلُ عظيمةٌ؛ فضائِلُ عامَّةٌ، وفضائِلُ في آياتٍ وسُوَرٍ خاصَّةٍ؛ مثلًا الفاتحةُ هي السَّبعُ المثاني وهي أمُّ الكِتابِ، آيةُ الكرسيِّ هي أعظَمُ آيةٍ في كِتابِ الله، وهَلُمَّ جَرًّا، هناك آياتٌ أو سُوَرٌ لها فضلٌ خاصٌّ، أمَّا القُرْآنُ عمومًا فله أيضًا فضائِلُ عامَّةٌ، وهذا يوجِبُ علينا أن نحرِصَ غايةَ الحِرصِ على تلاوةِ كِتابِ اللهِ عَزَّ وجَلَّ ليلًا ونهارًا) . | K27: فضل تلاوة القرآن ومدارسته، والحثّ على تلاوته ليلاً ونهاراً. | L27: ما فضل قراءة القرآن؟ | لماذا أقرأ القرآن؟ | هل في قراءة القرآن أجر؟ | ما فائدة الاجتماع على القرآن؟ | M27: أ | N27: لا | O27: حديث أبي هريرة: «وما اجتمع قوم في بيت من بيوت الله…» — صحيح مسلم (2699)؛ يُتحقق من رقمه في الموسوعة الحديثية | P27: محمد — 5 أكتوبر 2026 | R27: اعتُمد دون ملاحظات. | S27: =IF(A27="","",IF(OR(M27="ج",M27="د"),"المستوى لا يُنشر",IF(IFERROR(INDEX(المصادر!$F$2:$F$30,MATCH(D27,المصادر!$A$2:$A$30,0)),"")<>"نعم","المصدر غير معتمد",IF(OR(B27="",E27="",J27="",K27="",P27=""),"بيانات ناقصة",IF(AND(N27="نعم",Q27<>"موافق"),"ينقصه رأي المختص","صالح للنشر"))))) | U27: كيف أبدأ قراءة القرآن؟ | ما حكم قراءة القرآن للحائض؟
A28: ق-39 | B28: ح6 | C28: إضافي | D28: م-02 | E28: خصائص القرآن — المبحث السادس، المطلب الأول، الوجه 5: الحض على تعلم القرآن وتعليمه — https://dorar.net/aqeeda/1411 | I28: — | J28: 5- الحَضُّ على تعَلُّمِ القُرْآنِ وتعليمِه: عن عُثمانَ بنِ عَفَّانَ رَضِيَ اللهُ عنه، عن النَّبيِّ صلَّى اللهُ عليه وسلَّم قال: ((خيرُكم من تعلَّم القُرْآنَ وعَلَّمه )) . وكان النَّبيُّ صلَّى اللهُ عليه وسلَّم يحُثُّ أصحابَه رَضِيَ اللهُ عنهم على تعَلُّمِ القُرْآنِ وتعليمِه، وحِفْظِه وتحفيظِه، وكان يُقَدِّمُ أكثَرَهم أخذًا للقُرْآنِ في إمامةِ الصَّلَواتِ، وقيادةِ السَّرايا. | K28: الحثّ على تعلّم القرآن وتعليمه: «خيركم من تعلّم القرآن وعلّمه»، وكان النبي ﷺ يقدّم أكثر أصحابه أخذاً للقرآن. | L28: ما فضل تعلّم القرآن؟ | هل أتعلّم القرآن مع غيري؟ | خيركم من تعلم القرآن وعلمه | M28: أ | N28: لا | O28: حديث عثمان: «خيركم من تعلّم القرآن وعلّمه» — صحيح البخاري (5027) — يُتحقق من الرقم | P28: محمد — 5 أكتوبر 2026 | R28: اعتُمد دون ملاحظات. | S28: =IF(A28="","",IF(OR(M28="ج",M28="د"),"المستوى لا يُنشر",IF(IFERROR(INDEX(المصادر!$F$2:$F$30,MATCH(D28,المصادر!$A$2:$A$30,0)),"")<>"نعم","المصدر غير معتمد",IF(OR(B28="",E28="",J28="",K28="",P28=""),"بيانات ناقصة",IF(AND(N28="نعم",Q28<>"موافق"),"ينقصه رأي المختص","صالح للنشر"))))) | U28: أين أتعلم القرآن؟ | ما أحكام التجويد؟
A29: ق-10 | B29: ح2 | C29: أساسي | D29: م-03 | E29: مباحث في علوم القرآن، مناع القطان — الفصل 4: المكي والمدني — الفرق بين المكي والمدني (ص 60 حسب فهرس الكتاب) — https://quranpedia.net/book/23563 | F29: الفرق بين المكي والمدني | H29: ما الفرق بين المكي والمدني؟ | ما معنى سورة مكية؟ | ما معنى سورة مدنية؟ | I29: — | J29: للعلماء في الفرق بين المكي والمدني ثلاثة آراء اصطلاحية، كل رأي منها بُنِيَ على اعتبار خاص. الأول: اعتبار زمن النزول، فالمكي: ما نزل قبل الهجرة وإن كان بغير مكة، والمدني: ما نزل بعد الهجرة وإن كان بغير المدينة، فما نزل بعد الهجرة ولو بمكة، أو عرفة: مدني، كالذي نزل عام الفتح، كقوله تعالى: ﴿إِنَّ اللَّهَ يَأْمُرُكُمْ أَنْ تُؤَدُّوا الْأَمَانَاتِ إِلَى أَهْلِهَا﴾ [النساء: 58]، فإنها نزلت بمكة في جوف الكعبة عام الفتح الأعظم، أو نزل بحجة الوداع كقوله تعالى: ﴿الْيَوْمَ أَكْمَلْتُ لَكُمْ دِينَكُمْ وَأَتْمَمْتُ عَلَيْكُمْ نِعْمَتِي وَرَضِيتُ لَكُمُ الْإِسْلَامَ دِينًا﴾ [المائدة: 3]، وهذا الرأي أولى من الرأيين بعده لحصره واطراده. […] | K29: معنى «مكي» و«مدني»: المكي ما نزل قبل الهجرة، والمدني ما نزل بعدها، وهو أرجح الآراء الثلاثة. | L29: ما معنى سورة مكية ومدنية؟ | يعني إيش مكية؟ | ليش مكتوب على السورة مدنية؟ | هل المكي ما نزل في مكة فقط؟ | M29: أ | N29: لا | O29: النساء 58 (جزء)؛ المائدة 3 (جزء) — تُعرض من المصحف. | P29: محمد — 5 أكتوبر 2026 | R29: اعتُمد دون ملاحظات. | S29: =IF(A29="","",IF(OR(M29="ج",M29="د"),"المستوى لا يُنشر",IF(IFERROR(INDEX(المصادر!$F$2:$F$30,MATCH(D29,المصادر!$A$2:$A$30,0)),"")<>"نعم","المصدر غير معتمد",IF(OR(B29="",E29="",J29="",K29="",P29=""),"بيانات ناقصة",IF(AND(N29="نعم",Q29<>"موافق"),"ينقصه رأي المختص","صالح للنشر"))))) | U29: ما الفرق بين أسلوب السور المكية والمدنية؟ | في أي شهر نزل القرآن؟
A30: ق-05 | B30: ح5 | C30: أساسي | D30: م-03 | E30: مباحث في علوم القرآن، مناع القطان — الفصل 4: المكي والمدني — مدخل الفصل (ص 49–50 حسب فهرس الكتاب) — https://quranpedia.net/book/23563 | F30: خصائص الآيات المكية والمدنية | H30: ما موضوعات القرآن؟ | عن ماذا يتكلم القرآن؟ | ما الرسالة الأساسية في القرآن؟ | I30: — | J30: والذي يقرأ القرآن الكريم يجد للآيات المكية خصائص ليست للآيات المدنية في وقعها ومعانيها، وإن كانت الثانية مبنية على الأولى في الأحكام والتشريع. فحيث كان القوم في جاهلية تعمى وتصم، يعبدون الأوثان، ويشركون بالله، وينكرون الوحي، ويكذبون بيوم الدين […] نزل الوحي المكي قوارع زاجرة، وشهبًا منذرة، وحججًا قاطعة، يحطم وثنيتهم في العقيدة، ويدعوهم إلى توحيد الألوهية والربوبية، ويهتك أستار فسادهم، ويسَفِّه أحلامهم، ويقيم دلائل النبوة، ويضرب الأمثلة للحياة الآخرة وما فيها من جنة ونار، ويتحداهم -على فصاحتهم- بأن يأتوا بمثل القرآن، ويسوق إليهم قصص المكذبين الغابرين عبرة وذكرى […] وحين تكونت الجماعة المؤمنة بالله وملائكته وكتبه ورسله واليوم الآخر وبالقدر خيره وشره، وامتُحنت في عقيدتها بأذى المشركين فصبرت وهاجرت بدينها مؤثرة ما عند الله على متع الحياة -حين تكونت هذه الجماعة- نرى الآيات المدنية طويلة المقاطع، تتناول أحكام الإسلام وحدوده، وتدعو إلى الجهاد والاستشهاد في سبيل الله، وتفصل أصول التشريع، وتضع قواعد المجتمع، وتحدد روابط الأسرة، وصلات الأفراد، وعلاقات الدول والأمم، كما تفضح المنافقين وتكشف دخيلتهم، وتجادل أهل الكتاب وتلجم أفواههم -وهذا هو الطابع العام للقرآن المدني. | K30: أبرز موضوعات القرآن: التوحيد، ودلائل النبوة، والآخرة والجنة والنار، وقصص الأمم السابقة، ثم الأحكام وقواعد المجتمع والأسرة. | L30: عن ماذا يتكلم القرآن؟ | ما الرسالة الأساسية في القرآن؟ | هل القرآن كتاب أحكام فقط؟ | هل يتكلم القرآن عن يوم القيامة؟ | ماذا يطلب القرآن من الإنسان؟ | M30: أ | N30: نعم | O30: — | P30: محمد — 5 أكتوبر 2026 | Q30: موافق | R30: مقطع حساس: وافق المختص الأعلم. | S30: =IF(A30="","",IF(OR(M30="ج",M30="د"),"المستوى لا يُنشر",IF(IFERROR(INDEX(المصادر!$F$2:$F$30,MATCH(D30,المصادر!$A$2:$A$30,0)),"")<>"نعم","المصدر غير معتمد",IF(OR(B30="",E30="",J30="",K30="",P30=""),"بيانات ناقصة",IF(AND(N30="نعم",Q30<>"موافق"),"ينقصه رأي المختص","صالح للنشر"))))) | U30: ما قصة يوسف عليه السلام؟ | ما تفسير سورة الفاتحة؟
A31: ق-06 | B31: ح5 | C31: أساسي | D31: م-03 | E31: مباحث في علوم القرآن، مناع القطان — الفصل 21: قصص القرآن — معنى القصص، وأنواعه، وفوائده (ص 316–317 حسب فهرس الكتاب) — https://quranpedia.net/book/23563 | F31: قصص القرآن | H31: هل في القرآن قصص؟ | ما قصص القرآن؟ | هل يذكر القرآن الأنبياء؟ | I31: — | J31: وقصص القرآن: أخباره عن أحوال الأمم الماضية، والنبوات السابقة، والحوادث الواقعة - وقد اشتمل القرآن على كثير من وقائع الماضي، وتاريخ الأمم، وذكر البلاد والديار، وتتبع آثار كل قوم، وحكى عنهم صورة ناطقة لما كانوا عليه. والقصص في القرآن ثلاثة أنواع: النوع الأول: قصص الأنبياء، وقد تضمن دعوتهم إلى قومهم، والمعجزات التي أيدهم الله بها، وموقف المعاندين منهم، ومراحل الدعوة وتطورها وعاقبة المؤمنين والمكذبين، كقصص نوح، وإبراهيم، وموسى، وهارون، وعيسى، ومحمد، وغيرهم من الأنبياء والمرسلين، عليهم جميعًا أفضل الصلاة والسلام. […] النوع الثالث: قصص يتعلق بالحوادث التي وقعت في زمن رسول الله -صلى الله عليه وسلم- كغزوة بدر وأحد في سورة آل عمران، وغزوة حنين وتبوك في التوبة، وغزوة الأحزاب في سورة الأحزاب، والهجرة، والإسراء، ونحو ذلك. وللقصص القرآني فوائد نجمل أهمها فيما يأتي: 1- إيضاح أسس الدعوة إلى الله، وبيان أصول الشرائع التي بعث بها كل نبي: ﴿وَمَا أَرْسَلْنَا مِنْ قَبْلِكَ مِنْ رَسُولٍ إِلَّا نُوحِي إِلَيْهِ أَنَّهُ لَا إِلَهَ إِلَّا أَنَا فَاعْبُدُونِ﴾ [الأنبياء: 25]. […] | K31: هل في القرآن قصص؟ نعم: قصص الأنبياء، وأحداث زمن النبي ﷺ، والغاية منها بيان أسس الدعوة إلى التوحيد. | L31: هل القرآن فيه قصص؟ | هل يذكر القرآن موسى وعيسى؟ | ليش القرآن يحكي قصص الأنبياء؟ | هل قصص القرآن حقيقية؟ | M31: أ | N31: لا | O31: الأنبياء 25 (كاملة) — تُعرض من المصحف. | P31: محمد — 5 أكتوبر 2026 | R31: اعتُمد دون ملاحظات. | S31: =IF(A31="","",IF(OR(M31="ج",M31="د"),"المستوى لا يُنشر",IF(IFERROR(INDEX(المصادر!$F$2:$F$30,MATCH(D31,المصادر!$A$2:$A$30,0)),"")<>"نعم","المصدر غير معتمد",IF(OR(B31="",E31="",J31="",K31="",P31=""),"بيانات ناقصة",IF(AND(N31="نعم",Q31<>"موافق"),"ينقصه رأي المختص","صالح للنشر"))))) | U31: ما قصة نوح بالتفصيل؟ | هل قصص القرآن منقولة من التوراة؟
A32: ق-15 | B32: ح4 | C32: أساسي | D32: م-03 | E32: مباحث في علوم القرآن، مناع القطان — الفصل 8: جمع القرآن وترتيبه — ترتيب الآيات، وسور القرآن وآياته (ص 140، 145 حسب فهرس الكتاب) — https://quranpedia.net/book/23563 | F32: السورة والآية وعدد السور | H32: ما الفرق بين السورة والآية؟ | كم عدد سور القرآن؟ | كم عدد آيات القرآن؟ | I32: — | J32: القرآن سور وآيات منها القصار والطوال، والآية: هي الجملة من كلام الله المندرجة في سورة من القرآن، والسورة: هي الجملة من آيات القرآن ذات المطلع والمقطع. […] وتعداد السور: مائة وأربع عشرة سورة، وقيل: وثلاث عشرة بجعل الأنفال وبراءة سورة واحدة. أما تعداد الآيات فستة آلاف ومائتا آية، واختلفوا فيما زاد عن ذلك. وأطول الآيات آية الدَّيْن، وأطول السور سورة البقرة. وهذه التجزئة تيسر على الناس الحفظ، وتحملهم على الدراسة، وتشعر القارئ لسورة من السور بأنه قد أخذ قسطاً وافيًا وطائفة مستقلة من أصول دينه وأحكام شريعته. | K32: ما السورة وما الآية؟ وعدد سور القرآن 114 سورة، وآياته ستة آلاف ومئتان وزيادة. | L32: كم عدد سور القرآن؟ | ما الفرق بين السورة والآية؟ | كم آية في القرآن؟ | ما أطول سورة؟ | M32: أ | N32: لا | O32: — | P32: محمد — 5 أكتوبر 2026 | R32: اعتُمد دون ملاحظات. | S32: =IF(A32="","",IF(OR(M32="ج",M32="د"),"المستوى لا يُنشر",IF(IFERROR(INDEX(المصادر!$F$2:$F$30,MATCH(D32,المصادر!$A$2:$A$30,0)),"")<>"نعم","المصدر غير معتمد",IF(OR(B32="",E32="",J32="",K32="",P32=""),"بيانات ناقصة",IF(AND(N32="نعم",Q32<>"موافق"),"ينقصه رأي المختص","صالح للنشر"))))) | U32: من رتّب سور القرآن؟ | كيف أجد آية في المصحف؟
